<?xml version="1.0" ?>
<!-- =================================================================================== -->
<!-- |    This document was autogenerated by xacro from src/ur5_husky_main/urdf/robot/trajopt.xacro | -->
<!-- |    EDITING THIS FILE BY HAND IS NOT RECOMMENDED                                 | -->
<!-- =================================================================================== -->
<robot name="robot">
  <!-- Used to set k position in the safety controller-->
  <link name="world"/>
  <!-- <link name="floor">
    <visual>
        <origin xyz="0 0 -${wheel_radius - wheel_vertical_offset/2}" rpy="0 0 0" />
        <geometry>
          <box size="10 10 0.00005"/>
        </geometry>
        <material name="Floor">
          <color rgba="0.72 0.80 0.97 0.7"/>
        </material>
      </visual>
      <collision>
        <origin xyz="0 0 -${wheel_radius - wheel_vertical_offset/2}" rpy="0 0 0" />
        <geometry>
          <box size="10 10 0.00005"/>
        </geometry>
      </collision>
  </link> -->
  <gazebo>
    <plugin filename="libgazebo_ros_control.so" name="ros_control">
      <!--robotNamespace>/</robotNamespace-->
      <!--robotSimType>gazebo_ros_control/DefaultRobotHWSim</robotSimType-->
    </plugin>
    <!--
    <plugin name="gazebo_ros_power_monitor_controller" filename="libgazebo_ros_power_monitor.so">
      <alwaysOn>true</alwaysOn>
      <updateRate>1.0</updateRate>
      <timeout>5</timeout>
      <powerStateTopic>power_state</powerStateTopic>
      <powerStateRate>10.0</powerStateRate>
      <fullChargeCapacity>87.78</fullChargeCapacity>     
      <dischargeRate>-474</dischargeRate>
      <chargeRate>525</chargeRate>
      <dischargeVoltage>15.52</dischargeVoltage>
      <chargeVoltage>16.41</chargeVoltage>
    </plugin>
-->
  </gazebo>
  <link name="ur5_base_link">
    <visual>
      <origin rpy="0 0 3.141592653589793" xyz="0 0 0"/>
      <geometry>
        <mesh filename="package://ur_description/meshes/ur5/visual/base.dae"/>
      </geometry>
      <material name="LightGrey">
        <color rgba="0.7 0.7 0.7 1.0"/>
      </material>
    </visual>
    <collision>
      <origin rpy="0 0 3.141592653589793" xyz="0 0 0"/>
      <geometry>
        <mesh filename="package://ur_description/meshes/ur5/collision/base.stl"/>
      </geometry>
    </collision>
    <inertial>
      <mass value="4.0"/>
      <origin rpy="0 0 0" xyz="0 0 0"/>
      <inertia ixx="0.00443333156" ixy="0.0" ixz="0.0" iyy="0.00443333156" iyz="0.0" izz="0.0072"/>
    </inertial>
  </link>
  <link name="ur5_shoulder_link">
    <visual>
      <origin rpy="0 0 3.141592653589793" xyz="0 0 0"/>
      <geometry>
        <mesh filename="package://ur_description/meshes/ur5/visual/shoulder.dae"/>
      </geometry>
      <material name="LightGrey">
        <color rgba="0.7 0.7 0.7 1.0"/>
      </material>
    </visual>
    <collision>
      <origin rpy="0 0 3.141592653589793" xyz="0 0 0"/>
      <geometry>
        <mesh filename="package://ur_description/meshes/ur5/collision/shoulder.stl"/>
      </geometry>
    </collision>
    <inertial>
      <mass value="3.7"/>
      <origin rpy="0 0 0" xyz="0 0 0"/>
      <inertia ixx="0.014972352344389999" ixy="0.0" ixz="0.0" iyy="0.014972352344389999" iyz="0.0" izz="0.01040625"/>
    </inertial>
  </link>
  <link name="ur5_upper_arm_link">
    <visual>
      <origin rpy="1.5707963267948966 0 -1.5707963267948966" xyz="0 0 0.13585"/>
      <geometry>
        <mesh filename="package://ur_description/meshes/ur5/visual/upperarm.dae"/>
      </geometry>
      <material name="LightGrey">
        <color rgba="0.7 0.7 0.7 1.0"/>
      </material>
    </visual>
    <collision>
      <origin rpy="1.5707963267948966 0 -1.5707963267948966" xyz="0 0 0.13585"/>
      <geometry>
        <mesh filename="package://ur_description/meshes/ur5/collision/upperarm.stl"/>
      </geometry>
    </collision>
    <inertial>
      <mass value="8.393"/>
      <origin rpy="0 1.5707963267948966 0" xyz="-0.2125 0.0 0.136"/>
      <inertia ixx="0.1338857818623325" ixy="0.0" ixz="0.0" iyy="0.1338857818623325" iyz="0.0" izz="0.0151074"/>
    </inertial>
  </link>
  <link name="ur5_forearm_link">
    <visual>
      <origin rpy="1.5707963267948966 0 -1.5707963267948966" xyz="0 0 0.0165"/>
      <geometry>
        <mesh filename="package://ur_description/meshes/ur5/visual/forearm.dae"/>
      </geometry>
      <material name="LightGrey">
        <color rgba="0.7 0.7 0.7 1.0"/>
      </material>
    </visual>
    <collision>
      <origin rpy="1.5707963267948966 0 -1.5707963267948966" xyz="0 0 0.0165"/>
      <geometry>
        <mesh filename="package://ur_description/meshes/ur5/collision/forearm.stl"/>
      </geometry>
    </collision>
    <inertial>
      <mass value="2.275"/>
      <origin rpy="0 1.5707963267948966 0" xyz="-0.196125 0.0 0.0165"/>
      <inertia ixx="0.03121679102890359" ixy="0.0" ixz="0.0" iyy="0.03121679102890359" iyz="0.0" izz="0.004095"/>
    </inertial>
  </link>
  <link name="ur5_wrist_1_link">
    <visual>
      <origin rpy="1.5707963267948966 0 0" xyz="0 0 -0.093"/>
      <geometry>
        <mesh filename="package://ur_description/meshes/ur5/visual/wrist1.dae"/>
      </geometry>
      <material name="LightGrey">
        <color rgba="0.7 0.7 0.7 1.0"/>
      </material>
    </visual>
    <collision>
      <origin rpy="1.5707963267948966 0 0" xyz="0 0 -0.093"/>
      <geometry>
        <mesh filename="package://ur_description/meshes/ur5/collision/wrist1.stl"/>
      </geometry>
    </collision>
    <inertial>
      <mass value="1.219"/>
      <origin rpy="0 0 0" xyz="0 0 0"/>
      <inertia ixx="0.0020138887777775" ixy="0.0" ixz="0.0" iyy="0.0020138887777775" iyz="0.0" izz="0.0021942"/>
    </inertial>
  </link>
  <link name="ur5_wrist_2_link">
    <visual>
      <origin rpy="0 0 0" xyz="0 0 -0.095"/>
      <geometry>
        <mesh filename="package://ur_description/meshes/ur5/visual/wrist2.dae"/>
      </geometry>
      <material name="LightGrey">
        <color rgba="0.7 0.7 0.7 1.0"/>
      </material>
    </visual>
    <collision>
      <origin rpy="0 0 0" xyz="0 0 -0.095"/>
      <geometry>
        <mesh filename="package://ur_description/meshes/ur5/collision/wrist2.stl"/>
      </geometry>
    </collision>
    <inertial>
      <mass value="1.219"/>
      <origin rpy="0 0 0" xyz="0 0 0"/>
      <inertia ixx="0.0018310388509175" ixy="0.0" ixz="0.0" iyy="0.0018310388509175" iyz="0.0" izz="0.0021942"/>
    </inertial>
  </link>
  <link name="ur5_wrist_3_link">
    <visual>
      <origin rpy="1.5707963267948966 0 0" xyz="0 0 -0.0818"/>
      <geometry>
        <mesh filename="package://ur_description/meshes/ur5/visual/wrist3.dae"/>
      </geometry>
      <material name="LightGrey">
        <color rgba="0.7 0.7 0.7 1.0"/>
      </material>
    </visual>
    <collision>
      <origin rpy="1.5707963267948966 0 0" xyz="0 0 -0.0818"/>
      <geometry>
        <mesh filename="package://ur_description/meshes/ur5/collision/wrist3.stl"/>
      </geometry>
    </collision>
    <inertial>
      <mass value="0.1879"/>
      <origin rpy="0 0 0" xyz="0.0 0.0 -0.01525"/>
      <inertia ixx="8.062472608343e-05" ixy="0.0" ixz="0.0" iyy="8.062472608343e-05" iyz="0.0" izz="0.0001321171875"/>
    </inertial>
  </link>
  <joint name="ur5_shoulder_pan_joint" type="revolute">
    <parent link="ur5_base_link"/>
    <child link="ur5_shoulder_link"/>
    <origin rpy="0 0 0" xyz="0 0 0.089159"/>
    <axis xyz="0 0 1"/>
    <limit effort="150.0" lower="-6.283185307179586" upper="6.283185307179586" velocity="3.141592653589793"/>
    <dynamics damping="0" friction="0"/>
  </joint>
  <joint name="ur5_shoulder_lift_joint" type="revolute">
    <parent link="ur5_shoulder_link"/>
    <child link="ur5_upper_arm_link"/>
    <origin rpy="1.570796327 0 0" xyz="0 0 0"/>
    <axis xyz="0 0 1"/>
    <limit effort="150.0" lower="-6.283185307179586" upper="6.283185307179586" velocity="3.141592653589793"/>
    <dynamics damping="0" friction="0"/>
  </joint>
  <joint name="ur5_elbow_joint" type="revolute">
    <parent link="ur5_upper_arm_link"/>
    <child link="ur5_forearm_link"/>
    <origin rpy="0 0 0" xyz="-0.425 0 0"/>
    <axis xyz="0 0 1"/>
    <limit effort="150.0" lower="-3.141592653589793" upper="3.141592653589793" velocity="3.141592653589793"/>
    <dynamics damping="0" friction="0"/>
  </joint>
  <joint name="ur5_wrist_1_joint" type="revolute">
    <parent link="ur5_forearm_link"/>
    <child link="ur5_wrist_1_link"/>
    <origin rpy="0 0 0" xyz="-0.39225 0 0.10915"/>
    <axis xyz="0 0 1"/>
    <limit effort="28.0" lower="-6.283185307179586" upper="6.283185307179586" velocity="3.141592653589793"/>
    <dynamics damping="0" friction="0"/>
  </joint>
  <joint name="ur5_wrist_2_joint" type="revolute">
    <parent link="ur5_wrist_1_link"/>
    <child link="ur5_wrist_2_link"/>
    <origin rpy="1.570796327 0 0" xyz="0 -0.09465 -1.941303950897609e-11"/>
    <axis xyz="0 0 1"/>
    <limit effort="28.0" lower="-6.283185307179586" upper="6.283185307179586" velocity="3.141592653589793"/>
    <dynamics damping="0" friction="0"/>
  </joint>
  <joint name="ur5_wrist_3_joint" type="revolute">
    <parent link="ur5_wrist_2_link"/>
    <child link="ur5_wrist_3_link"/>
    <origin rpy="1.570796326589793 3.141592653589793 3.141592653589793" xyz="0 0.0823 -1.688001216681175e-11"/>
    <axis xyz="0 0 1"/>
    <limit effort="28.0" lower="-6.283185307179586" upper="6.283185307179586" velocity="3.141592653589793"/>
    <dynamics damping="0" friction="0"/>
  </joint>
  <!-- Tool -->
  <joint name="ur5_ee_fixed_joint" type="fixed">
    <parent link="ur5_wrist_3_link"/>
    <child link="ur5_ee_link"/>
    <!-- Корректировка offset гриппера -->
    <origin rpy="0 -1.5707963267948966 0" xyz="0 0 0.015"/>
  </joint>
  <link name="ur5_ee_link">
    <collision>
      <geometry>
        <box size="0.01 0.01 0.01"/>
      </geometry>
      <origin rpy="0 0 0" xyz="-0.01 0 0"/>
    </collision>
  </link>
  <link name="ur5_tool0"/>
  <joint name="ur5_wrist_3_link-tool0_fixed_joint" type="fixed">
    <origin rpy="-1.5707963267948966 0 0" xyz="0 0 0"/>
    <parent link="ur5_wrist_3_link"/>
    <child link="ur5_tool0"/>
  </joint>
  <!-- Floor base -->
  <transmission name="ur5_shoulder_pan_trans">
    <type>transmission_interface/SimpleTransmission</type>
    <joint name="ur5_shoulder_pan_joint">
      <hardwareInterface>hardware_interface/PositionJointInterface</hardwareInterface>
    </joint>
    <actuator name="ur5_shoulder_pan_motor">
      <mechanicalReduction>1</mechanicalReduction>
    </actuator>
  </transmission>
  <transmission name="ur5_shoulder_lift_trans">
    <type>transmission_interface/SimpleTransmission</type>
    <joint name="ur5_shoulder_lift_joint">
      <hardwareInterface>hardware_interface/PositionJointInterface</hardwareInterface>
    </joint>
    <actuator name="ur5_shoulder_lift_motor">
      <mechanicalReduction>1</mechanicalReduction>
    </actuator>
  </transmission>
  <transmission name="ur5_elbow_trans">
    <type>transmission_interface/SimpleTransmission</type>
    <joint name="ur5_elbow_joint">
      <hardwareInterface>hardware_interface/PositionJointInterface</hardwareInterface>
    </joint>
    <actuator name="ur5_elbow_motor">
      <mechanicalReduction>1</mechanicalReduction>
    </actuator>
  </transmission>
  <transmission name="ur5_wrist_1_trans">
    <type>transmission_interface/SimpleTransmission</type>
    <joint name="ur5_wrist_1_joint">
      <hardwareInterface>hardware_interface/PositionJointInterface</hardwareInterface>
    </joint>
    <actuator name="ur5_wrist_1_motor">
      <mechanicalReduction>1</mechanicalReduction>
    </actuator>
  </transmission>
  <transmission name="ur5_wrist_2_trans">
    <type>transmission_interface/SimpleTransmission</type>
    <joint name="ur5_wrist_2_joint">
      <hardwareInterface>hardware_interface/PositionJointInterface</hardwareInterface>
    </joint>
    <actuator name="ur5_wrist_2_motor">
      <mechanicalReduction>1</mechanicalReduction>
    </actuator>
  </transmission>
  <transmission name="ur5_wrist_3_trans">
    <type>transmission_interface/SimpleTransmission</type>
    <joint name="ur5_wrist_3_joint">
      <hardwareInterface>hardware_interface/PositionJointInterface</hardwareInterface>
    </joint>
    <actuator name="ur5_wrist_3_motor">
      <mechanicalReduction>1</mechanicalReduction>
    </actuator>
  </transmission>
  <gazebo reference="ur5_shoulder_link">
    <selfCollide>true</selfCollide>
  </gazebo>
  <gazebo reference="ur5_upper_arm_link">
    <selfCollide>true</selfCollide>
  </gazebo>
  <gazebo reference="ur5_forearm_link">
    <selfCollide>true</selfCollide>
  </gazebo>
  <gazebo reference="ur5_wrist_1_link">
    <selfCollide>true</selfCollide>
  </gazebo>
  <gazebo reference="ur5_wrist_3_link">
    <selfCollide>true</selfCollide>
  </gazebo>
  <gazebo reference="ur5_wrist_2_link">
    <selfCollide>true</selfCollide>
  </gazebo>
  <gazebo reference="ur5_ee_link">
    <selfCollide>true</selfCollide>
  </gazebo>
  <!-- ROS base_link to UR 'Base' Coordinates transform -->
  <link name="ur5_base"/>
  <joint name="ur5_base_link-base_fixed_joint" type="fixed">
    <!-- NOTE: this rotation is only needed as long as base_link itself is
                 not corrected wrt the real robot (ie: rotated over 180
                 degrees)
      -->
    <origin rpy="0 0 -3.141592653589793" xyz="0 0 0.3"/>
    <parent link="ur5_base_link"/>
    <child link="ur5_base"/>
  </joint>
  <joint name="gripper_base_joint" type="fixed">
    <parent link="ur5_ee_link"/>
    <child link="gripper_base_link"/>
    <origin rpy="1.570795 0 0" xyz="0 0 0"/>
  </joint>
  <link name="gripper_base_link">
    <visual>
      <geometry>
        <mesh filename="package://robotiq_85_description/meshes/visual/robotiq_85_base_link.dae"/>
      </geometry>
    </visual>
    <collision>
      <geometry>
        <mesh filename="package://robotiq_85_description/meshes/collision/robotiq_85_base_link.stl"/>
      </geometry>
    </collision>
    <inertial>
      <mass value="0.636951"/>
      <origin xyz="0.0 0.0 0.0"/>
      <inertia ixx="0.000380" ixy="0.000000" ixz="0.000000" iyx="0.000000" iyy="0.001110" iyz="0.000000" izx="0.000000" izy="0.000000" izz="0.001171"/>
    </inertial>
  </link>
  <gazebo reference="gripper_base_link">
    <implicitSpringDamper>1</implicitSpringDamper>
    <mu1>100000</mu1>
    <mu2>100000</mu2>
    <kp>100000000.0</kp>
    <kd>1.0</kd>
  </gazebo>
  <joint name="gripper_finger1_joint" type="revolute">
    <parent link="gripper_base_link"/>
    <child link="gripper_finger1_knuckle_link"/>
    <axis xyz="0 0 1"/>
    <origin rpy="3.141592653589793 0.0 0.0" xyz="0.05490451627 0.03060114443 0.0"/>
    <limit effort="1000" lower="0.0" upper="0.804" velocity="2.0"/>
  </joint>
  <joint name="gripper_finger2_joint" type="revolute">
    <parent link="gripper_base_link"/>
    <child link="gripper_finger2_knuckle_link"/>
    <axis xyz="0 0 1"/>
    <origin rpy="0.0 0.0 0.0" xyz="0.05490451627 -0.03060114443 0.0"/>
    <limit effort="1000" lower="-3.14" upper="3.14" velocity="100.0"/>
    <mimic joint="gripper_finger1_joint"/>
  </joint>
  <link name="gripper_finger1_knuckle_link">
    <visual>
      <geometry>
        <mesh filename="package://robotiq_85_description/meshes/visual/robotiq_85_knuckle_link.dae"/>
      </geometry>
    </visual>
    <collision>
      <geometry>
        <mesh filename="package://robotiq_85_description/meshes/collision/robotiq_85_knuckle_link.stl"/>
      </geometry>
    </collision>
    <inertial>
      <mass value="0.018491"/>
      <origin xyz="0.0 0.0 0.0"/>
      <inertia ixx="0.000009" ixy="-0.000001" ixz="0.000000" iyx="-0.000001" iyy="0.000001" iyz="0.000000" izx="0.000000" izy="0.000000" izz="0.000010"/>
    </inertial>
  </link>
  <gazebo reference="gripper_finger1_knuckle_link">
    <implicitSpringDamper>1</implicitSpringDamper>
    <mu1>100000</mu1>
    <mu2>100000</mu2>
    <kp>100000000.0</kp>
    <kd>1.0</kd>
  </gazebo>
  <link name="gripper_finger2_knuckle_link">
    <visual>
      <geometry>
        <mesh filename="package://robotiq_85_description/meshes/visual/robotiq_85_knuckle_link.dae"/>
      </geometry>
    </visual>
    <collision>
      <geometry>
        <mesh filename="package://robotiq_85_description/meshes/collision/robotiq_85_knuckle_link.stl"/>
      </geometry>
    </collision>
    <inertial>
      <mass value="0.018491"/>
      <origin xyz="0.0 0.0 0.0"/>
      <inertia ixx="0.000009" ixy="-0.000001" ixz="0.000000" iyx="-0.000001" iyy="0.000001" iyz="0.000000" izx="0.000000" izy="0.000000" izz="0.000010"/>
    </inertial>
  </link>
  <gazebo reference="gripper_finger2_knuckle_link">
    <implicitSpringDamper>1</implicitSpringDamper>
    <mu1>100000</mu1>
    <mu2>100000</mu2>
    <kp>100000000.0</kp>
    <kd>1.0</kd>
  </gazebo>
  <joint name="gripper_finger1_finger_joint" type="fixed">
    <parent link="gripper_finger1_knuckle_link"/>
    <child link="gripper_finger1_finger_link"/>
    <origin rpy="0 0 0" xyz="-0.00408552455 -0.03148604435 0.0"/>
  </joint>
  <joint name="gripper_finger2_finger_joint" type="fixed">
    <parent link="gripper_finger2_knuckle_link"/>
    <child link="gripper_finger2_finger_link"/>
    <origin rpy="0 0 0" xyz="-0.00408552455 -0.03148604435 0.0"/>
  </joint>
  <link name="gripper_finger1_finger_link">
    <visual>
      <geometry>
        <mesh filename="package://robotiq_85_description/meshes/visual/robotiq_85_finger_link.dae"/>
      </geometry>
    </visual>
    <collision>
      <geometry>
        <mesh filename="package://robotiq_85_description/meshes/collision/robotiq_85_finger_link.stl"/>
      </geometry>
    </collision>
    <inertial>
      <mass value="0.027309"/>
      <origin xyz="0.0 0.0 0.0"/>
      <inertia ixx="0.000003" ixy="-0.000002" ixz="0.000000" iyx="-0.000002" iyy="0.000021" iyz="0.000000" izx="0.000000" izy="0.000000" izz="0.000020"/>
    </inertial>
  </link>
  <gazebo reference="gripper_finger1_finger_link">
    <implicitSpringDamper>1</implicitSpringDamper>
    <mu1>100000</mu1>
    <mu2>100000</mu2>
    <kp>100000000.0</kp>
    <kd>1.0</kd>
  </gazebo>
  <link name="gripper_finger2_finger_link">
    <visual>
      <geometry>
        <mesh filename="package://robotiq_85_description/meshes/visual/robotiq_85_finger_link.dae"/>
      </geometry>
    </visual>
    <collision>
      <geometry>
        <mesh filename="package://robotiq_85_description/meshes/collision/robotiq_85_finger_link.stl"/>
      </geometry>
    </collision>
    <inertial>
      <mass value="0.027309"/>
      <origin xyz="0.0 0.0 0.0"/>
      <inertia ixx="0.000003" ixy="-0.000002" ixz="0.000000" iyx="-0.000002" iyy="0.000021" iyz="0.000000" izx="0.000000" izy="0.000000" izz="0.000020"/>
    </inertial>
  </link>
  <gazebo reference="gripper_finger2_finger_link">
    <implicitSpringDamper>1</implicitSpringDamper>
    <mu1>100000</mu1>
    <mu2>100000</mu2>
    <kp>100000000.0</kp>
    <kd>1.0</kd>
  </gazebo>
  <joint name="gripper_finger1_inner_knuckle_joint" type="continuous">
    <parent link="gripper_base_link"/>
    <child link="gripper_finger1_inner_knuckle_link"/>
    <axis xyz="0 0 1"/>
    <origin rpy="3.141592653589793 0.0 0.0" xyz="0.06142 0.0127 0"/>
    <limit effort="0.1" lower="-3.14" upper="3.14" velocity="100.0"/>
    <mimic joint="gripper_finger1_joint" offset="0"/>
  </joint>
  <joint name="gripper_finger2_inner_knuckle_joint" type="continuous">
    <parent link="gripper_base_link"/>
    <child link="gripper_finger2_inner_knuckle_link"/>
    <axis xyz="0 0 1"/>
    <origin rpy="0 0 0" xyz="0.06142 -0.0127 0"/>
    <limit effort="0.1" lower="-3.14" upper="3.14" velocity="100.0"/>
    <mimic joint="gripper_finger1_joint" offset="0"/>
  </joint>
  <link name="gripper_finger1_inner_knuckle_link">
    <visual>
      <geometry>
        <mesh filename="package://robotiq_85_description/meshes/visual/robotiq_85_inner_knuckle_link.dae"/>
      </geometry>
    </visual>
    <collision>
      <geometry>
        <mesh filename="package://robotiq_85_description/meshes/collision/robotiq_85_inner_knuckle_link.stl"/>
      </geometry>
    </collision>
    <inertial>
      <mass value="0.029951"/>
      <origin xyz="0.0 0.0 0.0"/>
      <inertia ixx="0.000039" ixy="0.000000" ixz="0.000000" iyx="0.000000" iyy="0.000005" iyz="0.000000" izx="0.000000" izy="0.000000" izz="0.000035"/>
    </inertial>
  </link>
  <gazebo reference="gripper_finger1_inner_knuckle_link">
    <implicitSpringDamper>1</implicitSpringDamper>
    <mu1>100000</mu1>
    <mu2>100000</mu2>
    <kp>100000000.0</kp>
    <kd>1.0</kd>
  </gazebo>
  <link name="gripper_finger2_inner_knuckle_link">
    <visual>
      <geometry>
        <mesh filename="package://robotiq_85_description/meshes/visual/robotiq_85_inner_knuckle_link.dae"/>
      </geometry>
    </visual>
    <collision>
      <geometry>
        <mesh filename="package://robotiq_85_description/meshes/collision/robotiq_85_inner_knuckle_link.stl"/>
      </geometry>
    </collision>
    <inertial>
      <mass value="0.029951"/>
      <origin xyz="0.0 0.0 0.0"/>
      <inertia ixx="0.000039" ixy="0.000000" ixz="0.000000" iyx="0.000000" iyy="0.000005" iyz="0.000000" izx="0.000000" izy="0.000000" izz="0.000035"/>
    </inertial>
  </link>
  <gazebo reference="gripper_finger2_inner_knuckle_link">
    <implicitSpringDamper>1</implicitSpringDamper>
    <mu1>100000</mu1>
    <mu2>100000</mu2>
    <kp>100000000.0</kp>
    <kd>1.0</kd>
  </gazebo>
  <joint name="gripper_finger1_finger_tip_joint" type="continuous">
    <parent link="gripper_finger1_inner_knuckle_link"/>
    <child link="gripper_finger1_finger_tip_link"/>
    <axis xyz="0 0 1"/>
    <origin rpy="0.0 0.0 0.0" xyz="0.04303959807 -0.03759940821 0.0"/>
    <limit effort="0.1" lower="-3.14" upper="3.14" velocity="100.0"/>
    <mimic joint="gripper_finger1_joint" multiplier="-1"/>
  </joint>
  <joint name="gripper_finger2_finger_tip_joint" type="continuous">
    <parent link="gripper_finger2_inner_knuckle_link"/>
    <child link="gripper_finger2_finger_tip_link"/>
    <axis xyz="0 0 1"/>
    <origin rpy="0.0 0.0 0.0" xyz="0.04303959807 -0.03759940821  0.0"/>
    <limit effort="0.1" lower="-3.14" upper="3.14" velocity="100.0"/>
    <mimic joint="gripper_finger1_joint" multiplier="-1"/>
  </joint>
  <link name="gripper_finger1_finger_tip_link">
    <visual>
      <geometry>
        <mesh filename="package://robotiq_85_description/meshes/visual/robotiq_85_finger_tip_link.dae"/>
      </geometry>
    </visual>
    <collision>
      <geometry>
        <mesh filename="package://robotiq_85_description/meshes/collision/robotiq_85_finger_tip_link.stl"/>
      </geometry>
    </collision>
    <inertial>
      <mass value="0.019555"/>
      <origin xyz="0.0 0.0 0.0"/>
      <inertia ixx="0.000002" ixy="0.000000" ixz="0.000000" iyx="0.000000" iyy="0.000005" iyz="0.000000" izx="0.000000" izy="0.000000" izz="0.000006"/>
    </inertial>
  </link>
  <gazebo reference="gripper_finger1_finger_tip_link">
    <implicitSpringDamper>1</implicitSpringDamper>
    <mu1>100000</mu1>
    <mu2>100000</mu2>
    <kp>100000000.0</kp>
    <kd>1.0</kd>
  </gazebo>
  <link name="gripper_finger2_finger_tip_link">
    <visual>
      <geometry>
        <mesh filename="package://robotiq_85_description/meshes/visual/robotiq_85_finger_tip_link.dae"/>
      </geometry>
    </visual>
    <collision>
      <geometry>
        <mesh filename="package://robotiq_85_description/meshes/collision/robotiq_85_finger_tip_link.stl"/>
      </geometry>
    </collision>
    <inertial>
      <mass value="0.019555"/>
      <origin xyz="0.0 0.0 0.0"/>
      <inertia ixx="0.000002" ixy="0.000000" ixz="0.000000" iyx="0.000000" iyy="0.000005" iyz="0.000000" izx="0.000000" izy="0.000000" izz="0.000006"/>
    </inertial>
  </link>
  <gazebo reference="gripper_finger2_finger_tip_link">
    <implicitSpringDamper>1</implicitSpringDamper>
    <mu1>100000</mu1>
    <mu2>100000</mu2>
    <kp>100000000.0</kp>
    <kd>1.0</kd>
  </gazebo>
  <gazebo>
    <plugin filename="libgazebo_grasp_fix.so" name="gazebo_grasp_fix">
      <arm>
        <arm_name>gripper_arm</arm_name>
        <palm_link>ur5_ee_link</palm_link>
        <gripper_link>gripper_finger1_finger_tip_link</gripper_link>
        <gripper_link>gripper_finger2_finger_tip_link</gripper_link>
      </arm>
      <forces_angle_tolerance>100</forces_angle_tolerance>
      <update_rate>2</update_rate>
      <grip_count_threshold>1</grip_count_threshold>
      <max_grip_count>2</max_grip_count>
      <release_tolerance>0.005</release_tolerance>
      <disable_collisions_on_attach>true</disable_collisions_on_attach>
      <contact_topic>__default_topic__</contact_topic>
    </plugin>
  </gazebo>
  <transmission name="gripper_finger1_trans">
    <type>transmission_interface/SimpleTransmission</type>
    <joint name="gripper_finger1_joint">
      <hardwareInterface>PositionJointInterface</hardwareInterface>
    </joint>
    <actuator name="gripper_finger1_motor">
      <mechanicalReduction>1</mechanicalReduction>
      <hardwareInterface>PositionJointInterface</hardwareInterface>
    </actuator>
  </transmission>
  <gazebo>
    <!-- loading plugin: mimic joints works in gazebo now -->
    <plugin filename="libroboticsgroup_gazebo_mimic_joint_plugin.so" name="mimic_robotiq_85_1">
      <joint>gripper_finger1_joint</joint>
      <mimicJoint>gripper_finger2_joint</mimicJoint>
      <!--multiplier>1.0</multiplier>
                <offset>0.0</offset-->
    </plugin>
    <plugin filename="libroboticsgroup_gazebo_mimic_joint_plugin.so" name="mimic_robotiq_85_2">
      <joint>gripper_finger1_joint</joint>
      <mimicJoint>gripper_finger2_inner_knuckle_joint</mimicJoint>
      <!--multiplier>1.0</multiplier>
                <offset>0.0</offset-->
    </plugin>
    <plugin filename="libroboticsgroup_gazebo_mimic_joint_plugin.so" name="mimic_robotiq_85_3">
      <joint>gripper_finger1_joint</joint>
      <mimicJoint>gripper_finger1_inner_knuckle_joint</mimicJoint>
      <!--multiplier>1.0</multiplier>
                <offset>0.0</offset-->
    </plugin>
    <plugin filename="libroboticsgroup_gazebo_mimic_joint_plugin.so" name="mimic_robotiq_85_4">
      <joint>gripper_finger1_joint</joint>
      <mimicJoint>gripper_finger1_finger_tip_joint</mimicJoint>
      <multiplier>-1.0</multiplier>
      <offset>0.0</offset>
    </plugin>
    <plugin filename="libroboticsgroup_gazebo_mimic_joint_plugin.so" name="mimic_robotiq_85_5">
      <joint>gripper_finger1_joint</joint>
      <mimicJoint>gripper_finger2_finger_tip_joint</mimicJoint>
      <multiplier>-1.0</multiplier>
      <offset>0.0</offset>
    </plugin>
  </gazebo>
  <material name="dark_grey">
    <color rgba="0.2 0.2 0.2 1.0"/>
  </material>
  <material name="medium_grey">
    <color rgba="0.6 0.6 0.6 1.0"/>
  </material>
  <material name="light_grey">
    <color rgba="0.8 0.8 0.8 1.0"/>
  </material>
  <material name="yellow">
    <color rgba="0.8 0.8 0.0 1.0"/>
  </material>
  <material name="black">
    <color rgba="0.15 0.15 0.15 1.0"/>
  </material>
  <material name="white">
    <color rgba="1.0 1.0 1.0 1.0"/>
  </material>
  <material name="red">
    <color rgba="1.0 0.0 0.0 1.0"/>
  </material>
  <!-- Spawn the sensor arch link -->
  <link name="sensor_arch_mount_link">
    <origin rpy="0 0 0" xyz="0 0 0"/>
    <visual>
      <geometry>
        <mesh filename="package://husky_description/meshes/accessories/510_mm_sensor_arch.dae"/>
      </geometry>
    </visual>
    <collision>
      <origin rpy="0 0 0" xyz="0 0 0"/>
      <geometry>
        <mesh filename="package://husky_description/meshes/accessories/510_mm_sensor_arch.dae"/>
      </geometry>
    </collision>
  </link>
  <!-- Attach the sensor arch to the top plate -->
  <joint name="sensor_arch_mount" type="fixed">
    <origin rpy="0 0 3.14159" xyz="-0.32 0 0.51"/>
    <parent link="top_plate_link"/>
    <child link="sensor_arch_mount_link"/>
  </joint>
  <!-- </xacro:if> -->
  <!-- Base link is the center of the robot's bottom plate -->
  <link name="base_link">
    <visual>
      <origin rpy="0 0 0" xyz="0 0 0"/>
      <geometry>
        <mesh filename="package://husky_description/meshes/base_link.dae"/>
      </geometry>
    </visual>
    <!-- <collision>
        <origin xyz="${( husky_front_bumper_extend - husky_rear_bumper_extend ) / 2.0} 0 ${base_z_size/4}" rpy="0 0 0" />
        <geometry>
          <box size="${ base_x_size + husky_front_bumper_extend + husky_rear_bumper_extend } ${base_y_size} ${base_z_size/2}"/>
        </geometry>
      </collision>
      <collision>
        <origin xyz="0 0 ${base_z_size*3/4-0.01}" rpy="0 0 0" />
        <geometry>
          <box size="${base_x_size*4/5} ${base_y_size} ${base_z_size/2-0.02}"/>
        </geometry>
      </collision> -->
  </link>
  <!-- Base footprint is on the ground under the robot -->
  <link name="base_footprint"/>
  <joint name="base_footprint_joint" type="fixed">
    <origin rpy="0 0 0" xyz="0 0 -0.11728000000000001"/>
    <parent link="base_link"/>
    <child link="base_footprint"/>
  </joint>
  <!-- Inertial link stores the robot's inertial information -->
  <link name="inertial_link">
    <inertial>
      <mass value="46.034"/>
      <origin xyz="-0.00065 -0.085 0.062"/>
      <inertia ixx="0.6022" ixy="-0.02364" ixz="-0.1197" iyy="1.7386" iyz="-0.001544" izz="2.0296"/>
    </inertial>
  </link>
  <joint name="inertial_joint" type="fixed">
    <origin rpy="0 0 0" xyz="0 0 0"/>
    <parent link="base_link"/>
    <child link="inertial_link"/>
  </joint>
  <link name="front_left_wheel">
    <inertial>
      <mass value="2.637"/>
      <origin xyz="0 0 0"/>
      <inertia ixx="0.02467" ixy="0" ixz="0" iyy="0.04411" iyz="0" izz="0.02467"/>
    </inertial>
    <visual>
      <origin rpy="0 0 0" xyz="0 0 0"/>
      <geometry>
        <mesh filename="package://husky_description/meshes/wheel.dae" scale="0.86 0.86 0.86"/>
      </geometry>
    </visual>
    <collision>
      <origin rpy="1.570795 0 0" xyz="0 0 0"/>
      <geometry>
        <cylinder length="0.1143" radius="0.1501"/>
      </geometry>
    </collision>
  </link>
  <gazebo reference="front_left_wheel">
    <mu1 value="1.0"/>
    <mu2 value="0.5"/>
    <kp value="10000000.0"/>
    <kd value="1.0"/>
    <fdir1 value="1 0 0"/>
  </gazebo>
  <joint name="front_left_wheel_joint" type="continuous">
    <parent link="base_link"/>
    <child link="front_left_wheel"/>
    <origin rpy="0 0 0" xyz="0.256 0.2854 0.03282"/>
    <axis rpy="0 0 0" xyz="0 1 0"/>
  </joint>
  <link name="front_right_wheel">
    <inertial>
      <mass value="2.637"/>
      <origin xyz="0 0 0"/>
      <inertia ixx="0.02467" ixy="0" ixz="0" iyy="0.04411" iyz="0" izz="0.02467"/>
    </inertial>
    <visual>
      <origin rpy="0 0 0" xyz="0 0 0"/>
      <geometry>
        <mesh filename="package://husky_description/meshes/wheel.dae" scale="0.86 0.86 0.86"/>
      </geometry>
    </visual>
    <collision>
      <origin rpy="1.570795 0 0" xyz="0 0 0"/>
      <geometry>
        <cylinder length="0.1143" radius="0.1501"/>
      </geometry>
    </collision>
  </link>
  <gazebo reference="front_right_wheel">
    <mu1 value="1.0"/>
    <mu2 value="0.5"/>
    <kp value="10000000.0"/>
    <kd value="1.0"/>
    <fdir1 value="1 0 0"/>
  </gazebo>
  <joint name="front_right_wheel_joint" type="continuous">
    <parent link="base_link"/>
    <child link="front_right_wheel"/>
    <origin rpy="0 0 0" xyz="0.256 -0.2854 0.03282"/>
    <axis rpy="0 0 0" xyz="0 1 0"/>
  </joint>
  <link name="rear_left_wheel">
    <inertial>
      <mass value="2.637"/>
      <origin xyz="0 0 0"/>
      <inertia ixx="0.02467" ixy="0" ixz="0" iyy="0.04411" iyz="0" izz="0.02467"/>
    </inertial>
    <visual>
      <origin rpy="0 0 0" xyz="0 0 0"/>
      <geometry>
        <mesh filename="package://husky_description/meshes/wheel.dae" scale="0.86 0.86 0.86"/>
      </geometry>
    </visual>
    <collision>
      <origin rpy="1.570795 0 0" xyz="0 0 0"/>
      <geometry>
        <cylinder length="0.1143" radius="0.1501"/>
      </geometry>
    </collision>
  </link>
  <gazebo reference="rear_left_wheel">
    <mu1 value="1.0"/>
    <mu2 value="0.5"/>
    <kp value="10000000.0"/>
    <kd value="1.0"/>
    <fdir1 value="1 0 0"/>
  </gazebo>
  <joint name="rear_left_wheel_joint" type="continuous">
    <parent link="base_link"/>
    <child link="rear_left_wheel"/>
    <origin rpy="0 0 0" xyz="-0.256 0.2854 0.03282"/>
    <axis rpy="0 0 0" xyz="0 1 0"/>
  </joint>
  <link name="rear_right_wheel">
    <inertial>
      <mass value="2.637"/>
      <origin xyz="0 0 0"/>
      <inertia ixx="0.02467" ixy="0" ixz="0" iyy="0.04411" iyz="0" izz="0.02467"/>
    </inertial>
    <visual>
      <origin rpy="0 0 0" xyz="0 0 0"/>
      <geometry>
        <mesh filename="package://husky_description/meshes/wheel.dae" scale="0.86 0.86 0.86"/>
      </geometry>
    </visual>
    <collision>
      <origin rpy="1.570795 0 0" xyz="0 0 0"/>
      <geometry>
        <cylinder length="0.1143" radius="0.1501"/>
      </geometry>
    </collision>
  </link>
  <gazebo reference="rear_right_wheel">
    <mu1 value="1.0"/>
    <mu2 value="0.5"/>
    <kp value="10000000.0"/>
    <kd value="1.0"/>
    <fdir1 value="1 0 0"/>
  </gazebo>
  <joint name="rear_right_wheel_joint" type="continuous">
    <parent link="base_link"/>
    <child link="rear_right_wheel"/>
    <origin rpy="0 0 0" xyz="-0.256 -0.2854 0.03282"/>
    <axis rpy="0 0 0" xyz="0 1 0"/>
  </joint>
  <!-- Spawn Husky chassis -->
  <link name="top_chassis_link">
    <visual>
      <origin rpy="0 0 0" xyz="0 0 0"/>
      <geometry>
        <mesh filename="package://husky_description/meshes/top_chassis.dae"/>
      </geometry>
    </visual>
  </link>
  <!-- Attach chassis to the robot -->
  <joint name="top_chassis_joint" type="fixed">
    <parent link="base_link"/>
    <child link="top_chassis_link"/>
  </joint>
  <!-- Spawn front bumper link -->
  <link name="front_bumper_link">
    <visual>
      <geometry>
        <mesh filename="package://husky_description/meshes/bumper.dae"/>
      </geometry>
    </visual>
  </link>
  <!-- Attach front bumper -->
  <joint name="front_bumper" type="fixed">
    <origin rpy="0 0 0" xyz="0.48 0 0.091"/>
    <parent link="base_link"/>
    <child link="front_bumper_link"/>
  </joint>
  <!-- Spawn rear bumper link -->
  <link name="rear_bumper_link">
    <visual>
      <geometry>
        <mesh filename="package://husky_description/meshes/bumper.dae"/>
      </geometry>
    </visual>
  </link>
  <!-- Attach rear bumper -->
  <joint name="rear_bumper" type="fixed">
    <origin rpy="0 0 3.14159" xyz="-0.48 0 0.091"/>
    <parent link="base_link"/>
    <child link="rear_bumper_link"/>
  </joint>
  <!-- <xacro:if value="$(optenv HUSKY_TOP_PLATE_ENABLED true)"> -->
  <!-- Spawn the top plate -->
  <!-- <xacro:if value="$(optenv HUSKY_LARGE_TOP_PLATE true)"> -->
  <link name="top_plate_link">
    <visual>
      <origin rpy="0 0 0" xyz="0 0 0"/>
      <geometry>
        <mesh filename="package://husky_description/meshes/large_top_plate.dae"/>
      </geometry>
    </visual>
    <collision>
      <origin rpy="0 0 0" xyz="0 0 0"/>
      <geometry>
        <mesh filename="package://husky_description/meshes/large_top_plate_collision.stl"/>
      </geometry>
    </collision>
  </link>
  <!-- Attach top plate -->
  <joint name="top_plate_joint" type="fixed">
    <parent link="base_link"/>
    <child link="top_plate_link"/>
    <origin rpy="0 0 0" xyz="0.0812 0 0.2255"/>
  </joint>
  <!-- Top plate front link -->
  <joint name="top_plate_front_joint" type="fixed">
    <parent link="top_plate_link"/>
    <child link="top_plate_front_link"/>
    <origin rpy="0 0 0" xyz="0.4125 0 0.00672"/>
  </joint>
  <!-- Top plate rear link-->
  <joint name="top_plate_rear_joint" type="fixed">
    <parent link="top_plate_link"/>
    <child link="top_plate_rear_link"/>
    <origin rpy="0 0 0" xyz="-0.4125 0 0.00672"/>
  </joint>
  <!-- </xacro:if> -->
  <!-- <xacro:unless value="$(optenv HUSKY_LARGE_TOP_PLATE true)">
        <link name="top_plate_link">
          <visual>
            <origin xyz="0 0 0" rpy="0 0 0" />
            <geometry>
              <mesh filename="package://husky_description/meshes/top_plate.dae" />
            </geometry>
          </visual>
          <collision>
            <origin xyz="0 0 0" rpy="0 0 0"/>
            <geometry>
              <mesh filename="package://husky_description/meshes/top_plate.stl" />
            </geometry>
          </collision>
        </link>-->
  <!-- Attach top plate -->
  <!-- <joint name="top_plate_joint" type="fixed">
          <parent link="base_link" />
          <child link="top_plate_link"/>
          <origin xyz="0.0812 0 0.245" rpy="0 0 0"/>
        </joint> -->
  <!-- Top plate front link -->
  <!-- <joint name="top_plate_front_joint" type="fixed">
          <parent link="top_plate_link" />
          <child link="top_plate_front_link"/>
          <origin xyz="0.36367 0 0.00639" rpy="0 0 0"/>
        </joint> -->
  <!-- Top plate rear link-->
  <!--<joint name="top_plate_rear_joint" type="fixed">
          <parent link="top_plate_link" />
          <child link="top_plate_rear_link"/>
          <origin xyz="-0.36633 0 0.00639" rpy="0 0 0"/>
        </joint>
      </xacro:unless> -->
  <link name="top_plate_front_link"/>
  <link name="top_plate_rear_link"/>
  <!-- </xacro:if> -->
  <link name="bumper_link">
    <inertial>
      <origin rpy="0 0 0" xyz="0 0 0"/>
      <mass value="0.0000000000001"/>
      <inertia ixx="0.00000001" ixy="0.00000001" ixz="0.00000001" iyy="0.00000001" iyz="0.00000001" izz="0.00000001"/>
    </inertial>
    <!-- <collision name="base_link_fixed_joint_lump__robot/bumper_link">
          <origin rpy="0 0 0" xyz="0 0 0.1"/>
          <geometry>
              <box size="1.0 0.7 0.31"/>
          </geometry>
      </collision> -->
  </link>
  <joint name="bumper_joint" type="fixed">
    <origin rpy="0.0 0.0 0.0" xyz="0 0 0"/>
    <parent link="base_link"/>
    <child link="bumper_link"/>
  </joint>
  <!-- This file is a placeholder which is included by default from
       husky.urdf.xacro. If a robot is being customized and requires
       additional URDF, set the HUSKY_URDF_EXTRAS environment variable
       to the full path of the file you would like included. -->
  <!-- This file is a placeholder which is included by default from
       husky.urdf.xacro. If a robot is being customized and requires
       additional URDF, set the HUSKY_URDF_EXTRAS environment variable
       to the full path of the file you would like included. -->
  <!-- <joint name="floor_to_world" type="fixed">
    <parent link="world"/>
    <child link="floor"/> -->
  <!-- не трогать xyz и rpy, иначе не считает траекторию! -->
  <!-- <origin xyz="0 0 0" rpy="0 0 0"/>
  </joint> -->
  <joint name="base_link_to_floor" type="fixed">
    <parent link="world"/>
    <child link="base_link"/>
    <!-- не трогать xyz и rpy, иначе не считает траекторию! -->
    <origin rpy="0 0 0" xyz="0 0 0.1201"/>
  </joint>
  <joint name="ur5_to_base_link" type="fixed">
    <parent link="top_plate_link"/>
    <child link="ur5_base_link"/>
    <!--  Позиционирование робота на телеге -->
    <origin rpy="0 0 1.570795" xyz="0.3035 0.01 0.0"/>
  </joint>
</robot>

